Workbook

Sheet 🛡️ Risk Register
A1: BLAISE KINGKO — GRC INTELLIGENCE & RISK REGISTER [ ARCHIVED SNAPSHOT: v11 — 2026-09-21 — NOT LIVE ]
A2: ARCHIVED SNAPSHOT: v11 — 2026-09-21 — NOT LIVE. This is a frozen historical copy — do not edit. The current, authoritative register is GRC_Intelligence_Risk_Register.xlsx. | Sources: CISA KEV | US-CERT | NIST NVD | AWS/Azure Bulletins | AI Governance Updates | CISA/NSA/FBI Advisories | Frameworks: NIST CSF 2.0 | ISO 27001 | NIST 800-53 | CIS Controls | NIST AI RMF | ISO 42001 | EU AI Act | Last Updated: 2026-09-21 | See '📋 Version Log' tab for history.
A3: RISK ID | B3: DATE IDENTIFIED | C3: SOURCE | D3: CVE / ADVISORY ID | E3: THREAT / VULN | F3: THREAT CATEGORY | G3: AFFECTED ASSET | H3: AFFECTED SYSTEM | I3: FRAMEWORK MAPPING | J3: CONTROL FAMILY | K3: LIKELIHOOD (1-5) | L3: IMPACT (1-5) | M3: RISK SCORE | N3: RISK RATING | O3: INHERENT RISK | P3: CURRENT CONTROLS | Q3: RESIDUAL RISK | R3: REMEDIATION | S3: CIS CONTROL REF | T3: OWNER | U3: STATUS | V3: DUE DATE | W3: LAST UPDATED | X3: NOTES
A5: RR-001 | B5: 2026-05-29 | C5: CISA KEV | D5: CVE-2024-21887 | E5: Ivanti Connect Secure — Command Injection vulnerability actively exploited in the wild | F5: IT — Network | G5: VPN / Remote Access | H5: Ivanti Connect Secure | I5: NIST CSF 2.0: PR.PS-04, DE.CM-01 | NIST 800-53: SI-2, RA-5 | ISO 27001: A.12.6.1 | CIS Control 7 | J5: SI — System Integrity | K5: 5 | L5: 5 | M5: =K5*L5 | N5: Critical | O5: Critical | P5: Patch management process in place; WAF deployed | Q5: High | R5: Apply vendor patch immediately; isolate affected systems pending patch | S5: CIS Control 7.4 — Manage Operating System Vulnerabilities | T5: Blaise Kingko | U5: Open | V5: 2026-06-04 | W5: 2026-05-29 | X5: Actively exploited per CISA KEV. Patch available. Escalate to CISO immediately.
A6: RR-002 | B6: 2026-05-29 | C6: NIST NVD | D6: CVE-2025-0282 | E6: Ivanti Policy Secure — Stack-based buffer overflow enabling unauthenticated RCE | F6: IT — Application | G6: Policy Management Platform | H6: Ivanti Policy Secure | I6: NIST CSF 2.0: PR.PS-04, RS.MI-02 | NIST 800-53: SI-3, SC-39 | ISO 27001: A.14.2.2 | CIS Control 2 | J6: SC — System & Comms Protection | K6: 4 | L6: 5 | M6: =K6*L6 | N6: Critical | O6: Critical | P6: Network segmentation partially implemented | Q6: High | R6: Emergency patch deployment; conduct IOC sweep; review authentication logs | S6: CIS Control 2.2 — Ensure Software is Supported by Vendor | T6: Blaise Kingko | U6: Mitigating | V6: 2026-06-07 | W6: 2026-05-29 | X6: RCE vector. Pre-auth. Requires immediate patch cycle bypass for emergency deployment.
A7: RR-003 | B7: 2026-05-29 | C7: AWS Security Bulletin | D7: AWS-2025-001 | E7: AWS IAM confused deputy issue in cross-account role assumption — potential privilege escalation | F7: Cloud — IAM | G7: AWS Multi-Account Environment | H7: AWS IAM / STS | I7: NIST CSF 2.0: PR.AA-05 | NIST 800-53: AC-6, AC-2 | ISO 27001: A.9.2.3 | CIS Control 5 | J7: AC — Access Control | K7: 3 | L7: 4 | M7: =K7*L7 | N7: High | O7: High | P7: SCPs deployed; least-privilege IAM model in place across 500+ accounts | Q7: Medium | R7: Audit all cross-account trust relationships; enforce ExternalId conditions on all assume-role policies | S7: CIS Control 5.4 — Restrict Administrator Privileges | T7: Blaise Kingko | U7: Mitigating | V7: 2026-06-14 | W7: 2026-05-29 | X7: Leverage existing IAM governance model. SCP guardrails reduce blast radius significantly.
A8: RR-004 | B8: 2026-05-29 | C8: AI Governance Update | D8: EU-AI-ACT-2025-HIGH-RISK | E8: EU AI Act High-Risk AI System classification — internal LLM applications may require conformity assessment | F8: AI/ML — Governance | G8: Internal LLM Applications | H8: GenAI Platform (AWS Bedrock) | I8: NIST AI RMF: GOVERN 1.1, MAP 1.5 | ISO 42001: 6.1.2 | EU AI Act: Article 9, Annex III | NIST 800-53: SA-11 | J8: AI Risk Governance | K8: 3 | L8: 5 | M8: =K8*L8 | N8: High | O8: High | P8: AI Governance program active; NIST AI RMF framework implemented; prompt injection controls deployed | Q8: Medium | R8: Conduct EU AI Act conformity assessment; document intended purpose and risk management system; prepare technical documentation per Article 11 | S8: N/A — AI Governance Framework | T8: Blaise Kingko | U8: Open | V8: 2026-07-01 | W8: 2026-06-29 | X8: Regulatory deadline risk. EU AI Act enforcement begins Aug 2026. High-risk classification triggers conformity assessment requirement. REVISED 2026-06-29: European Parliament finalized amendments (approved 2026-06-16) delaying specific Annex III high-risk compliance deadlines; classification criteria unchanged. See AI-Governance/2026-06-EU-AI-Act-HighRisk-Classification-UPDATE for full change analysis.
A9: RR-005 | B9: 2026-05-29 | C9: US-CERT | D9: AA25-071A | E9: CISA Advisory — SVR cyber actors targeting cloud environments via misconfigured service accounts | F9: Cloud — Identity | G9: Cloud Service Accounts | H9: AWS / Azure Service Principals | I9: NIST CSF 2.0: PR.AA-01, DE.AE-02 | NIST 800-53: AC-6, AU-12 | ISO 27001: A.9.4.4 | CIS Control 4 | J9: AC — Access Control | K9: 4 | L9: 4 | M9: =K9*L9 | N9: High | O9: High | P9: SIEM monitoring active; CloudTrail enabled; anomaly detection in place | Q9: Medium | R9: Audit all service account permissions; rotate credentials; implement Just-In-Time access for privileged service accounts | S9: CIS Control 4.7 — Manage Default Accounts | T9: Blaise Kingko | U9: Open | V9: 2026-06-11 | W9: 2026-05-29 | X9: Nation-state TTPs. Aligns with existing SIEM architecture. Review CloudWatch anomaly alerts immediately.
A10: RR-006 | B10: 2026-06-08 | C10: AWS Security Bulletin | D10: 2026-030-AWS | E10: Linux Kernel "Copy.fail"/"DirtyFrag" privilege-escalation family (CVE-2026-46300, CVE-2026-31431, CVE-2026-43284, CVE-2026-43500) — local LPE in espintcp/algif_aead/xfrm_user/esp modules affecting AWS self-managed compute | F10: Cloud-Security | G10: Cloud Compute Infrastructure (Self-Managed Linux Nodes) | H10: AWS EKS Worker Nodes / Bottlerocket / EC2 Linux Instances | I10: NIST CSF 2.0 PR.PS-02/DE.CM-09 | NIST 800-53 SI-2/CM-2/CM-6/RA-5 | ISO 27001 A.8.8/A.8.9 | CIS Control 7/4 | J10: SI-2, CM-6, RA-5 | K10: 3 | L10: 4 | M10: 12 | N10: High | O10: High | P10: AWS-managed control planes patched; customer self-managed compute (EKS/EC2/Bottlerocket) requires manual node rotation | Q10: Medium | R10: Roll EKS-optimized AMIs and Bottlerocket hosts to patched builds (Bottlerocket >= v1.61.0); confirm Fargate platform versions >= 2026-06-09; validate via CSPM scan for zero non-compliant kernels | S10: Control 7 (7.4) / Control 4 | T10: Cloud Platform Engineering | U10: Open | V10: 2026-06-22 | W10: 2026-06-15 | X10: Shared-responsibility seam — AWS patches control plane only; full case bundle in Cloud-Security/2026-06-AWS-Bulletin-Linux-Kernel-CopyFail REVISED 2026-06-15 — AWS Fargate patches deployed all regions by June 15. Customer EKS/Bottlerocket/EC2 action still required; Likelihood reduced 4→3.
A11: RR-007 | B11: 2026-06-08 | C11: Azure Security Update | D11: CVE-2026-48567 | E11: Azure HorizonDB Elevation of Privilege — authentication bypass by spoofing (CWE-290) in managed multi-tenant database control plane, CVSS 10.0 | F11: Cloud-Security | G11: Cloud Database Platform (Multi-Tenant Control Plane) | H11: Azure HorizonDB (Managed Database Service) | I11: NIST CSF 2.0 PR.AA-03/DE.CM-03/GV.SC-06 | NIST 800-53 IA-2/AC-3/SC-7/CA-7 | ISO 27001 A.5.15/A.8.5/A.5.23 | CIS Control 6/13 | J11: IA-2, AC-3, SC-7 | K11: 3 | L11: 5 | M11: 15 | N11: High | O11: Critical | P11: Microsoft platform-side patch pipeline (vendor-controlled); Entra ID conditional access as tenant-side compensating control | Q11: Low | R11: Confirm Microsoft platform patch applied via Azure Service Health; audit HorizonDB auth logs 2026-05-28 to 2026-06-04 for spoofing indicators; enforce Entra ID-only authentication and Conditional Access MFA | S11: Control 6 / Control 13 | T11: Cloud Security Architecture | U11: Open | V11: 2026-06-15 | W11: 2026-06-08 | X11: Vendor-side CVSS 10.0 flaw — verification & IAM hardening case; full bundle in Cloud-Security/2026-06-MSRC-Azure-HorizonDB
A12: RR-008 | B12: 2026-06-08 | C12: CISA KEV | D12: CVE-2026-45247 | E12: Mirasvit Full Page Cache Warmer (Magento/Adobe Commerce) — deserialization of untrusted data / PHP object injection enabling unauthenticated RCE, CVSS 9.8, actively exploited in the wild | F12: Cloud-Security | G12: E-Commerce Application Platform | H12: Magento 2 / Adobe Commerce (Mirasvit Full Page Cache Warmer extension) | I12: NIST CSF 2.0 PR.PS-02/DE.CM-01/RS.AN-03 | NIST 800-53 SI-2/SI-3/SI-10/IR-4 | ISO 27001 A.8.8/A.8.28/A.8.16 | CIS Control 16/7/17 | PCI-DSS v4.0 Req 6.3.3/11.3 | J12: SI-2, SI-3, SI-10 | K12: 5 | L12: 5 | M12: 25 | N12: Critical | O12: Critical | P12: WAF signatures (Imperva) available as interim compensating control; PCI-mandated file-integrity monitoring may detect web-shell drops | Q12: Low | R12: Update Mirasvit Full Page Cache Warmer to v1.11.12+ on all Magento 2/Adobe Commerce instances immediately (target 2026-06-10); conduct web-shell forensic sweep of pub/media, var/, app/code directories; engage PCI Forensic Investigator if IOCs found | S12: Control 16 (16.13) / Control 7 | T12: Application Security / E-commerce Engineering | U12: Open — Expedited | V12: 2026-06-10 | W12: 2026-06-08 | X12: CISA federal due date 2026-06-06; active exploitation confirmed by Sansec/Imperva/SecurityWeek; full bundle in Cloud-Security/2026-06-CISA-KEV-Magento-Mirasvit
A13: RR-009 | B13: 2026-06-08 | C13: AI Governance Update | D13: Draft Guidelines — High-Risk AI Classification (Consultation closed 2026-06-23) | E13: European Commission draft guidance on classifying AI systems as "high-risk" under EU AI Act Annex III; enforcement infrastructure being stood up; high-risk obligation deadlines extended to Dec 2027 / Aug 2028 | F13: AI-Governance | G13: AI System Governance & Compliance Program | H13: EU-Resident AI System Inventory (EU AI Act Annex III Scope) | I13: NIST AI RMF GOVERN/MAP (1.1, 5.1) | ISO 42001 Clauses 6.1.2/8.4/4.1 | EU AI Act Article 6/Annex III | GDPR Article 35 (DPIA overlap) | J13: GOVERN, MAP | K13: 3 | L13: 3 | M13: 9 | N13: Medium | O13: Medium-High | P13: Existing ISO 42001 risk-assessment processes (where implemented) and NIST AI RMF MAP practices provide a transferable methodology for classification | Q13: Low | R13: Compile complete AI-system inventory mapped to EU-resident exposure; classify each system against draft Annex III criteria using ISO 42001 Clause 8.4 template; consider submitting consultation feedback before 2026-06-23; build combined NIST AI RMF/ISO 42001/EU AI Act/GDPR evidence template | S13: N/A — Regulatory/Governance | T13: AI Governance Lead | U13: Open — Proactive | V13: 2026-09-08 | W13: 2026-06-29 | X13: 18-month runway to Dec 2027 milestone; full bundle in AI-Governance/2026-06-EU-AI-Act-HighRisk-Classification. REVISED 2026-06-29: Public consultation closed as scheduled 2026-06-23; European Parliament finalized deadline-delay amendments (approved 2026-06-16) for certain Annex III high-risk categories. Recommend maintaining program momentum despite timeline relief — see AI-Governance/2026-06-EU-AI-Act-HighRisk-Classification-UPDATE.
A14: RR-010 | B14: 2026-06-08 | C14: CISA KEV | D14: CVE-2025-48595 | E14: Android Framework integer overflow (CWE-190) enabling local elevation of privilege; CVSS 8.4; Google confirms limited, targeted exploitation (spyware/nation-state pattern); affects Android 14/15/16/16-QPR2 | F14: IT-OT-Threats | G14: Mobile / BYOD Endpoint Fleet | H14: Android 14 / 15 / 16 / 16-QPR2 — Managed & BYOD Devices | I14: NIST CSF 2.0 PR.PS-02/DE.CM-09 | NIST 800-53 SI-2/CM-6 | ISO 27001 A.8.8 | CIS Control 4 (Mobile/BYOD) | J14: SI-2, CM-6 | K14: 4 | L14: 3 | M14: 12 | N14: High | O14: Medium | P14: MDM/UEM enforcement of OS patch-level baselines on managed devices; app-vetting controls limiting locally-installed untrusted apps | Q14: Low | R14: Push June 2026 Android security patch level to all managed/BYOD devices via MDM/UEM within 7 days; flag any device failing to report patched build for conditional-access restriction | S14: Control 4 | T14: Endpoint / Mobility Engineering | U14: Open | V14: 2026-06-15 | W14: 2026-06-08 | X14: Register entry only — mobile/endpoint scope did not meet full-bundle threshold (no direct AWS/IAM/CSPM/AI-platform nexus); monitor for KEV escalation
A15: RR-011 | B15: 2026-06-15 | C15: CISA KEV | D15: CVE-2026-35273 | E15: Oracle PeopleSoft Enterprise PeopleTools (EMHub) — Missing authentication for critical function enabling unauthenticated RCE; CVSS 9.8; zero-day exploited by UNC6240 (ShinyHunters) May 27–June 9, 2026; active extortion campaign | F15: IT-OT-Threats / Financial-Services | G15: ERP Platform (HR, Finance, Student Administration) | H15: Oracle PeopleSoft PeopleTools 8.61 / 8.62 | I15: NIST CSF 2.0: PR.PS-04/DE.CM-01/RS.AN-03/RS.MI-02 | NIST 800-53: SI-2/IA-2/AC-3/SI-10/IR-4/AU-6 | ISO 27001: A.8.8/A.5.15/A.8.5/A.5.26 | CIS Control 7/12/17 | J15: SI-2, IA-2, AC-3, IR-4 | K15: 5 | L15: 5 | M15: 25 | N15: Critical | O15: Critical | P15: Network perimeter firewall; SIEM monitoring; vulnerability scanning (signatures not available during zero-day window) | Q15: Critical (without patch); High with VPN-only access compensating control | R15: Apply Oracle emergency patch for CVE-2026-35273 to all PeopleTools 8.61/8.62 by June 22; restrict internet-facing PeopleSoft portals to VPN/internal access immediately; conduct threat hunt for UNC6240 IOCs from Mandiant June 11 report; engage IR retainer if IOCs found; assess SEC 4-day disclosure obligation if breach confirmed | S15: CIS Control 7.4 / CIS Control 17.4 / CIS Control 12.2 | T15: Enterprise Application Engineering / GRC | U15: Open — Emergency | V15: 2026-06-22 | W15: 2026-06-15 | X15: CISA KEV added 2026-06-12; federal due date 2026-07-03 (BOD 26-04); zero-day exploited by ShinyHunters (UNC6240) extortion campaign; Oracle out-of-band patch available June 12; full bundle in IT-OT-Threats/2026-06-CISA-KEV-Oracle-PeopleSoft
A16: RR-012 | B16: 2026-06-15 | C16: MSRC | D16: CVE-2026-45657 | E16: Windows Kernel use-after-free RCE — wormable; CVSS 9.8; unauthenticated network attack, no user interaction; SYSTEM-level code execution; self-propagating exploit profile comparable to EternalBlue/WannaCry (June 2026 Patch Tuesday) | F16: Cloud-Security / IT-OT-Threats | G16: Windows Endpoints / Servers / Azure IaaS VMs / AWS EC2 Windows | H16: Windows 10, Windows 11, Windows Server 2019/2022/2025 (all supported versions) | I16: NIST CSF 2.0: PR.PS-04/PR.IR-01/DE.CM-09/RC.RP-01 | NIST 800-53: SI-2/CM-6/SC-7/CP-9/RA-5 | ISO 27001: A.8.8/A.8.9/A.8.22/A.8.13 | CIS Control 7/4/11/12 | J16: SI-2, CM-6, SC-7, CP-9 | K16: 4 | L16: 5 | M16: 20 | N16: Critical | O16: Critical | P16: Endpoint patch management (WSUS/Intune/SSM); network segmentation (NSGs/SGs/VPC); EDR (CrowdStrike/Defender); SMB east-west blocking partially implemented | Q16: High (without full patch deployment); Low after patch complete | R16: Deploy June 2026 Windows cumulative update to ALL endpoints and servers within 72 hours (by June 18); prioritize internet-facing, DCs, and cloud VMs; block SMB (TCP 445) between network segments immediately as worm containment control; verify immutable backups exist before possible exploitation; use Azure Update Manager / AWS SSM Patch Manager for cloud VM compliance | S16: CIS Control 7.4 / CIS Control 12.2 / CIS Control 11.2 | T16: Cloud Platform Engineering / Endpoint Engineering | U16: Open — Emergency | V16: 2026-06-18 | W16: 2026-06-15 | X16: No confirmed exploitation at disclosure; wormable profile = treat as imminent (ZDI EternalBlue comparison); June 2026 Patch Tuesday (198 CVEs, largest ever); full bundle in Cloud-Security/2026-06-MSRC-PatchTuesday-WormableKernel
A17: RR-013 | B17: 2026-06-15 | C17: MSRC | D17: CVE-2026-47291 | E17: Windows HTTP Protocol Stack (HTTP.sys) integer overflow/heap overflow RCE; CVSS 9.8; unauthenticated; single malicious HTTP packet achieves full server RCE; configurable registry mitigation available (MaxRequestBytes ≤ 65534) (June 2026 Patch Tuesday) | F17: Cloud-Security / IT-OT-Threats | G17: Internet-facing Windows Web Servers / Azure IaaS IIS / Cloud-hosted Web Infrastructure | H17: Windows HTTP.sys (all IIS/HTTP.sys-exposed Windows Server versions) | I17: NIST CSF 2.0: PR.PS-04/PR.PS-02/DE.CM-09 | NIST 800-53: SI-2/CM-6/SC-5/SC-7 | ISO 27001: A.8.8/A.8.9 | CIS Control 7/4/12 | J17: SI-2, CM-6, SC-7 | K17: 4 | L17: 5 | M17: 20 | N17: Critical | O17: Critical | P17: WAF; NSG inbound HTTP restrictions; endpoint patch management | Q17: Medium (with MaxRequestBytes registry workaround); Low after June 2026 patch applied | R17: IMMEDIATE: Set MaxRequestBytes registry value ≤ 65534 (default 16384) on all IIS/HTTP.sys servers via GPO/SSM — eliminates exposure without reboot. Then: apply June 2026 cumulative update to all internet-facing Windows web servers by June 16. Remove registry workaround after patch confirmed installed. | S17: CIS Control 7.4 / CIS Control 4.1 | T17: Cloud Platform Engineering / Windows Sysadmin | U17: Open — Emergency | V17: 2026-06-16 | W17: 2026-06-15 | X17: Registry compensating control available immediately (no reboot required); full bundle in Cloud-Security/2026-06-MSRC-PatchTuesday-WormableKernel (combined with RR-012)
A18: RR-014 | B18: 2026-06-15 | C18: CISA KEV | D18: CVE-2026-7473 | E18: Arista Networks EOS incomplete comparison vulnerability — processes non-configured tunnel traffic, bypassing tunnel policy enforcement; CVSS 6.9; actively exploited; NO VENDOR PATCH PLANNED | F18: IT-OT-Threats | G18: Enterprise Network Infrastructure / WAN / Data Center Switching | H18: Arista EOS (all affected versions with tunnel configurations) | I18: NIST CSF 2.0: PR.IR-01/DE.CM-01/GV.RM-06 | NIST 800-53: SC-7/AC-4/SI-4/RA-3 | ISO 27001: A.8.22/A.8.16/A.8.9 | CIS Control 12/13 | IEC 62443 Zone/Conduit model | J18: SC-7, AC-4, SI-4 | K18: 4 | L18: 4 | M18: 16 | N18: High | O18: High | P18: Network firewall; SIEM monitoring; existing tunnel configurations as intended (but now unreliable as security boundary) | Q18: Medium (with interface ACLs, NetFlow monitoring, and defense-in-depth inline firewall at critical boundaries) | R18: No patch available (vendor will not fix). Compensating controls: (1) Deploy explicit interface-level ACLs denying unexpected tunnel sources on all Arista EOS devices; (2) Enable NetFlow/sFlow telemetry on all affected devices with SIEM alerting for unexpected tunnel traffic; (3) For critical boundaries (OT/financial): deploy inline stateful firewall as defense-in-depth; (4) Execute formal risk acceptance with CISO/CRO sign-off by June 30. | S18: CIS Control 12.2 / CIS Control 13.6 | T18: Network Engineering / GRC | U18: Open — Compensating Controls / Risk Acceptance | V18: 2026-06-30 | W18: 2026-06-15 | X18: CISA KEV added 2026-06-09; BOD 26-04 due date June 30; Arista confirmed no patch planned; permanent unpatched state requires formal risk acceptance; IEC 62443 zone integrity implications for OT environments; full bundle in IT-OT-Threats/2026-06-CISA-KEV-Arista-EOS
A19: RR-015 | B19: 2026-06-15 | C19: CISA KEV | D19: CVE-2026-11645 | E19: Google Chromium V8 out-of-bounds read/write enabling sandbox escape and arbitrary code execution via crafted HTML page; CVSS 8.8; actively exploited via phishing/malvertising; also affects all Electron-based enterprise desktop apps (VS Code, Slack, etc.) | F19: IT-OT-Threats | G19: Enterprise Endpoints / User Workstations / Cloud Console Users | H19: Google Chrome, Microsoft Edge (Chromium), all Electron-based enterprise applications | I19: NIST CSF 2.0: PR.PS-04/DE.CM-04/PR.AT-01 | NIST 800-53: SI-2/SI-3/SC-18/AT-2 | ISO 27001: A.8.8/A.8.7/A.6.3/A.8.23 | CIS Control 7/9/14 | J19: SI-2, SI-3, SC-18 | K19: 5 | L19: 4 | M19: 20 | N19: Critical | O19: Critical | P19: Chrome auto-update (if not blocked); MDM/Intune browser policy; web content filtering; EDR endpoint protection; email security (DMARC/DKIM) | Q19: Medium (Chrome/Edge patched); pending Electron app inventory and vendor patch assessment | R19: Force Chrome and Edge update to latest stable via MDM/Intune — verify 100% compliance. Inventory all Electron-based enterprise apps and track embedded Chromium version for each. Push available Electron app updates; restrict unpatched Electron apps pending vendor fix. Update web filtering threat intel feeds. Send security awareness communication re: phishing/malvertising campaign. | S19: CIS Control 7.4 / CIS Control 9.2 / CIS Control 14.1 | T19: Endpoint Engineering / SOC | U19: Open — Emergency | V19: 2026-06-18 | W19: 2026-06-15 | X19: CISA KEV added 2026-06-09; BOD 26-04 due date June 30; key risk: Electron app coverage gap — Chrome auto-update alone insufficient; exploit is silent (no user prompt); session theft from cloud console workers is highest-probability impact; full bundle in IT-OT-Threats/2026-06-CISA-KEV-Chrome-V8
A20: RR-016 | B20: 2026-06-15 | C20: CISA KEV | D20: CVE-2026-20245 | E20: Cisco Catalyst SD-WAN Manager (vManage) authenticated local OS command injection enabling arbitrary command execution as root via crafted file; CVSS 7.8; actively exploited; root on SD-WAN Manager = control of entire enterprise WAN fabric | F20: IT-OT-Threats | G20: Enterprise WAN Infrastructure / Network Management Plane | H20: Cisco Catalyst SD-WAN Manager (vManage) | I20: NIST CSF 2.0: PR.AA-05/PR.PS-04/DE.CM-03 | NIST 800-53: SI-2/AC-6/AC-2/CM-3/AU-9 | ISO 27001: A.8.8/A.5.15/A.8.22/A.8.32 | CIS Control 5/7/8/12 | J20: SI-2, AC-6, AC-2, CM-3 | K20: 4 | L20: 5 | M20: 20 | N20: Critical | O20: Critical | P20: RBAC on vManage; network-level restriction (variable); audit logging; MFA (variable by org) | Q20: High until patched; Medium with MFA + management-segment restriction + audit alerting | R20: Apply Cisco security patch for CVE-2026-20245 immediately (target June 18). Simultaneously: audit all vManage accounts — remove inactive/shared accounts; enforce MFA on all admin accounts; restrict vManage to dedicated management network segment (no direct internet access); forward vManage audit logs to SIEM with alert on policy changes and file uploads; review logs from June 1–15 for exploitation indicators. | S20: CIS Control 5.4 / CIS Control 7.4 / CIS Control 8.2 | T20: Network Engineering / IAM | U20: Open — Emergency | V20: 2026-06-30 | W20: 2026-06-15 | X20: CISA KEV added 2026-06-09; BOD 26-04 due date June 30; authentication prerequisite (insider/compromised account); root on vManage = WAN-wide control; complementary PAM hardening critical; full bundle in IT-OT-Threats/2026-06-CISA-KEV-Cisco-SDWAN
A21: RR-017 | B21: 2026-06-22 | C21: CISA KEV | D21: CVE-2026-20262 | E21: Cisco Catalyst SD-WAN Manager (vManage) path traversal vulnerability allowing unauthenticated attacker to read/overwrite arbitrary files; CVSS 6.5; new vendor patch released this week; KEV-added 2026-06-15; distinct from CVE-2026-20245 (RR-016) — same product, different flaw | F21: IT-OT-Threats | G21: Enterprise WAN Infrastructure / Network Management Plane | H21: Cisco Catalyst SD-WAN Manager (vManage) | I21: NIST CSF 2.0: PR.PS-04/PR.DS-01/DE.CM-03 | NIST 800-53: SI-2/AC-3/SC-28 | ISO 27001: A.8.8/A.8.24 | CIS Control 7/12 | J21: SI-2, AC-3, SC-28 | K21: 4 | L21: 4 | M21: 16 | N21: High | O21: High | P21: Network-level restriction (variable); audit logging | Q21: Medium until patched; Low-Medium with management-segment restriction | R21: Apply Cisco patch for CVE-2026-20262 immediately (due 2026-06-29). Restrict vManage management interface to dedicated segment; review file-access logs for path traversal indicators. | S21: CIS Control 7.4 / CIS Control 12.2 | T21: Network Engineering / IAM | U21: Open — Emergency | V21: 2026-06-29 | W21: 2026-06-22 | X21: ESCALATE/UPDATE relative to RR-016 (CVE-2026-20245) — new, distinct KEV entry on same product family, not a revision; full bundle in IT-OT-Threats/2026-06-CISA-KEV-Cisco-SDWAN-UPDATE
... A54: RR-050 | B54: 2026-08-05 | C54: Jenkins Security Advisory | D54: CVE-2026-70426; CVE-2026-70427; CVE-2026-70428 | E54: Jenkins — JEP-200 deserialization filter bypass (Remoting fallback path) plus companion arbitrary-file-write findings enabling controller code execution; responsibly disclosed, no known ITW exploitation | F54: IT — CI/CD Platform | G54: CI/CD Orchestration Controller | H54: Jenkins weekly <=2.575 / LTS <=2.568.1 | I54: NIST CSF 2.0: PR.AA-05 | NIST 800-53: SI-2, AC-6, SC-39 | ISO 27001: A.8.25 | CIS Control 16.1, 4.1 | J54: AC — Access Control | K54: 3 | L54: 5 | M54: 15 | N54: High | O54: High | P54: Vendor patch available (2.576/2.568.2); workaround published for orgs unable to upgrade immediately | Q54: Low (post-patch + permission-scoping review) | R54: Upgrade to Jenkins weekly 2.576 / LTS 2.568.2; tighten Agent/Connect and Item/Configure/Item/Build permissions; check init.groovy.d/ and plugins/ for unauthorized files | S54: CIS Control 16.1 — Application Software Security | T54: Blaise Kingko | U54: Open — Standard Cycle | V54: 2026-08-17 | W54: 2026-08-10 | X54: Responsibly disclosed via Jenkins Bug Bounty Program (European Commission-sponsored); no confirmed ITW exploitation; exploitability gated by Agent/Connect or Item/Configure permissions. Case folder: Cloud-Security/2026-08-NIST-NVD-Jenkins-DeserializationFilterBypass
A55: RR-051 | B55: 2026-09-04 | C55: AWS Security Bulletin | D55: CVE-2026-85787; CVE-2026-85654 | E55: AWS Labs MCP servers for AI agents — incomplete SQL-validation denylist in postgres-mcp-server allows read-only bypass; template injection in dynamodb-mcp-server CDK generator enables code execution | F55: AI — Agent/Tooling (dual: Cloud-Security) | G55: AI Agent Database/Infrastructure Tooling | H55: awslabs.postgres-mcp-server (<1.1.7); awslabs.dynamodb-mcp-server (<=2.0.10) | I55: NIST AI RMF: MAP 5.1, MANAGE 4.1 | ISO 42001: 8.4 | NIST 800-53: SI-10, SA-11 | MITRE ATLAS: AML.T0053 | J55: SI — System Integrity (AI Agent Trust Boundary) | K55: 3 | L55: 4 | M55: =K55*L55 | N55: High | O55: High | P55: No known exploitation; vendor patches available same-day as disclosure | Q55: Low (post-patch + database-enforced least privilege) | R55: Upgrade postgres-mcp-server to 1.1.7+ and dynamodb-mcp-server to 2.1.6+; enforce least-privilege DB roles independent of app-level read-only flag | S55: N/A — AI agent architecture finding; see NIST AI RMF MANAGE 4.1 | T55: Blaise Kingko | U55: Open | V55: 2026-09-21 | W55: 2026-09-07 | X55: Second consecutive week with an AI-agent tool-invocation trust-boundary finding — see RR-049 (CoreBreak) precedent. Case folder: AI-Governance/2026-09-AWS-Bulletin-MCP-Server-InputValidation (dual: Cloud-Security)
A56: RR-052 | B56: 2026-09-01 | C56: AWS Security Bulletin | D56: CVE-2026-83551 | E56: Amazon SageMaker Python SDK — cleartext storage of HMAC signing key in @step/@remote pipeline component allows cross-user code execution in shared accounts | F56: AI — ML Platform (dual: Cloud-Security) | G56: ML Pipeline Execution Environment | H56: Amazon SageMaker Python SDK v3.11.0 and earlier; v2.256.0 and earlier | I56: NIST AI RMF: MAP 5.1 | ISO 42001: 6.1.2 | NIST 800-53: SC-28, IA-5 | NIST CSF 2.0: PR.AA-05 | J56: SC — System & Communications Protection (Credential Exposure) | K56: 3 | L56: 4 | M56: =K56*L56 | N56: High | O56: High | P56: Vendor patch available same day; no confirmed exploitation | Q56: Low (post-patch + key rotation) | R56: Upgrade SDK to v3.11.0+/v2.256.0+; rotate all HMAC signing keys in use pre-patch; review shared SageMaker domain tenant isolation | S56: N/A — credential exposure / AI platform finding | T56: Blaise Kingko | U56: Open | V56: 2026-09-21 | W56: 2026-09-07 | X56: Third AWS AI/ML-platform finding this run alongside RR-051 — reinforces pattern of AWS AI tooling expansion outpacing trust-boundary maturity. Case folder: AI-Governance/2026-09-AWS-Bulletin-SageMaker-HMACKeyExposure (dual: Cloud-Security)
A57: RR-053 | B57: 2026-09-02 | C57: CISA KEV | D57: CVE-2026-83548; CVE-2026-83549 | E57: SonicWall SMA1000 — pre-auth SSRF chained with OS command injection yields unauthenticated RCE on remote-access appliance; actively exploited | F57: IT — Network (Remote Access) | G57: VPN / Remote Access Gateway | H57: SonicWall SMA1000 (models 6210, 7210, 8200v); firmware 12.4.3 <=03453 / 12.5.0 <=02835 | I57: NIST CSF 2.0: PR.PS-01, DE.CM-01 | NIST 800-53: SC-7, AC-4, SI-10 | ISO 27001: A.8.20 | CIS Control 12.2 | J57: SC — System & Communications Protection (Boundary Protection) | K57: 5 | L57: 5 | M57: =K57*L57 | N57: Critical | O57: Critical | P57: Vendor firmware fix available; no workaround for the SSRF/chain itself | Q57: Low-Medium (post-patch + compromise investigation) | R57: Upgrade to firmware 12.4.3 build 03526+ or 12.5.0 build 02952+; engage vendor support for compromise assessment given confirmed active exploitation | S57: CIS Control 12.2 — Establish and Maintain a Secure Network Architecture | T57: Blaise Kingko | U57: Open — Emergency | V57: 2026-09-05 | W57: 2026-09-07 | X57: 3-day CISA deadline (shortest tier), already past at time of this run — treat as overdue-priority. Third publicly-reported SonicWall SMA1000 security event of 2026 (follows July MFA-seed-theft incident; no confirmed technical link). Case folder: IT-OT-Threats/2026-09-CISA-KEV-SonicWall-SMA1000-SSRFChain
A58: RR-054 | B58: 2026-08-31 | C58: CISA KEV | D58: CVE-2026-81578; CVE-2026-82078 | E58: PaperCut NG/MF — missing authentication chained with unsafe reflection yields unauthenticated RCE on print-management server | F58: IT — Print/Document Infrastructure | G58: Print Management Server | H58: PaperCut NG/MF (see 2026-08-27 vendor bulletin for exact version ranges) | I58: NIST CSF 2.0: PR.AA-01 | NIST 800-53: IA-2, CM-6 | ISO 27001: A.8.9 | CIS Control 12.2 | J58: IA — Identification & Authentication | K58: 4 | L58: 5 | M58: =K58*L58 | N58: Critical | O58: Critical | P58: Vendor patch available (2026-08-27 bulletin); >1,000 internet-exposed instances reported industry-wide | Q58: Low (post-patch + exposure remediation) | R58: Apply PaperCut fix per 2026-08-27 bulletin; restrict management interface to internal network; review logs for lateral-movement indicators given product's ransomware-initial-access history | S58: CIS Control 12.2 — Establish and Maintain a Secure Network Architecture | T58: Blaise Kingko | U58: Open — Emergency | V58: 2026-09-14 | W58: 2026-09-07 | X58: Same product line as 2023 Cl0p/Bl00Dy ransomware initial-access CVEs (different vulnerabilities). Treat print-management infrastructure with perimeter-appliance-level patch urgency. Case folder: IT-OT-Threats/2026-09-CISA-KEV-PaperCut-NGMF-AuthBypassRCE
A59: RR-055 | B59: 2026-09-02 | C59: CISA KEV | D59: CVE-2026-82329 | E59: JFrog Artifactory — improper authentication under default configuration allows unauthenticated attacker to obtain administrative privileges; actively exploited (admin token minting observed) | F59: IT — CI/CD Platform (Software Supply Chain) | G59: Artifact Repository / Package Registry | H59: JFrog Artifactory (self-hosted); patched versions 7.111.21, 7.117.28, 7.125.20, 7.133.29, 7.146.38, 7.161.20 | I59: NIST CSF 2.0: PR.AA-01 | NIST 800-53: IA-2, SR-3 | ISO 27001: A.5.19 | CIS Control 16.1 | J59: IA — Identification & Authentication | K59: 5 | L59: 5 | M59: =K59*L59 | N59: Critical | O59: Critical | P59: Vendor patch available; exploitation observed ~96 hours post-disclosure | Q59: Low (post-patch + admin token audit) | R59: Upgrade to patched Artifactory version per branch; rotate all administrative and API tokens; audit for unauthorized tokens minted during exposure window | S59: CIS Control 16.1 — Application Software Security | T59: Blaise Kingko | U59: Open — Register-Only | V59: 2026-09-05 | W59: 2026-09-07 | X59: Register-only per program scope precedent (RR-021/034/039/044) — full narrative bundle not built this run given case-load prioritization toward AI/AWS and perimeter-appliance findings; remediation guidance above is complete and actionable regardless. CI/CD/software-supply-chain category — same class as RR-050 (Jenkins).
A60: RR-056 | B60: 2026-09-02 | C60: CISA KEV | D60: CVE-2026-49869 | E60: Kestra OSS workflow orchestration engine — unauthenticated OS command injection allows arbitrary workflow creation/execution; actively exploited for reverse shells and cryptocurrency mining | F60: IT — Workflow/CI-CD Orchestration | G60: Workflow Orchestration Engine | H60: Kestra OSS (see GHSA-5vc5-wxxq-3fjx for affected versions) | I60: NIST CSF 2.0: PR.PS-04 | NIST 800-53: SI-10, AC-3 | CIS Control 16.1 | J60: SI — System Integrity | K60: 5 | L60: 4 | M60: =K60*L60 | N60: Critical | O60: Critical | P60: Vendor patch available | Q60: Low (post-patch) | R60: Upgrade to patched Kestra release per GHSA-5vc5-wxxq-3fjx; audit for unauthorized workflows, Docker container discovery activity, and cryptocurrency-miner processes | S60: CIS Control 16.1 — Application Software Security | T60: Blaise Kingko | U60: Open — Register-Only | V60: 2026-09-05 | W60: 2026-09-07 | X60: Register-only per program scope precedent (RR-021/034/039/044). Same disclosure wave as RR-055 (Artifactory) — both part of the 7-CVE KEV batch added 2026-09-02 covering reverse-shell and crypto-miner deployment activity.
A61: RR-057 | B61: 2026-09-02 | C61: CISA KEV | D61: CVE-2026-9586 | E61: Sangoma Switchvox VoIP/PBX platform — unauthenticated SQL injection allows arbitrary SQL execution against backend PostgreSQL database, including RCE; actively exploited (reverse shells deployed) | F61: IT — VoIP/Telephony Infrastructure | G61: VoIP/PBX System | H61: Sangoma Switchvox (see vendor release notes for affected versions) | I61: NIST CSF 2.0: PR.PS-04 | NIST 800-53: SI-10 | CIS Control 16.1 | J61: SI — System Integrity | K61: 5 | L61: 4 | M61: =K61*L61 | N61: Critical | O61: Critical | P61: Vendor patch available | Q61: Low (post-patch) | R61: Apply Sangoma Switchvox patch per vendor release notes; review database and application logs for unauthorized SQL execution or reverse-shell activity | S61: CIS Control 16.1 — Application Software Security | T61: Blaise Kingko | U61: Open — Register-Only | V61: 2026-09-05 | W61: 2026-09-07 | X61: Register-only per program scope precedent — narrower enterprise-relevance category (VoIP/PBX) than program's core cloud/AI/network focus, but logged given confirmed active exploitation. Part of 2026-09-02 7-CVE KEV batch.
A62: RR-058 | B62: 2026-09-02 | C62: CISA KEV | D62: CVE-2026-48710 | E62: Kludex Starlette (Python ASGI framework, underlies FastAPI and other frameworks) — HTTP request/response smuggling allows path injection into host, enabling authentication bypass in apps relying on reconstructed URL paths | F62: IT — Application Framework/Library | G62: Web Application Framework Component | H62: Starlette (see GHSA-86qp-5c8j-p5mr for affected versions) | I62: NIST CSF 2.0: PR.DS-02 | NIST 800-53: SC-8, SR-3 | CIS Control 16.1 | J62: SR — Supply Chain Risk Management | K62: 3 | L62: 3 | M62: =K62*L62 | N62: Medium | O62: Medium | P62: Vendor patch available; chainable with CVE-2026-42271 per CISA notes | Q62: Low (post-patch) | R62: Upgrade Starlette to patched version per GHSA-86qp-5c8j-p5mr in all applications (including FastAPI-based services) that depend on it; audit any authentication logic that relies on reconstructed URL paths | S62: CIS Control 16.1 — Application Software Security | T62: Blaise Kingko | U62: Open — Register-Only | V62: 2026-09-16 | W62: 2026-09-07 | X62: Register-only — open-source library affecting many downstream applications (FastAPI, etc.); no confirmed mass exploitation reported. Recommend inventory of internal apps depending on Starlette given transitive-dependency blast radius.
A63: RR-059 | B63: 2026-09-04 | C63: CISA KEV | D63: CVE-2026-85046 | E63: Google Chromium V8 — type confusion vulnerability allows sandboxed remote code execution via crafted HTML page; affects Chrome, Edge, Opera, and other Chromium-based browsers | F63: IT — Endpoint (Browser) | G63: End-User Web Browser | H63: Chromium-based browsers (Chrome, Edge, Opera) prior to vendor patch | I63: NIST CSF 2.0: PR.PS-04 | NIST 800-53: SI-2 | CIS Control 7.1 | J63: SI — System Integrity | K63: 4 | L63: 4 | M63: =K63*L63 | N63: High | O63: High | P63: Vendor patch available via auto-update (Chrome stable channel update) | Q63: Low (post-patch, largely auto-remediating via browser auto-update) | R63: Ensure browser auto-update is enabled fleet-wide; verify enterprise-managed Chrome/Edge deployments have received the patched build | S63: CIS Control 7.1 — Establish and Maintain a Vulnerability Management Process | T63: Blaise Kingko | U63: Open — Register-Only | V63: 2026-09-18 | W63: 2026-09-07 | X63: Register-only — recurring V8 zero-day pattern; see AI-Governance/Cloud-Security precedent case IT-OT-Threats/2026-06-CISA-KEV-Chrome-V8 for the program's prior full-bundle treatment of this vulnerability class. Fleet-wide browser auto-update posture is the durable control, not per-CVE case bundles.
A64: RR-060 | B64: 2026-08-30 | C64: Threat Intelligence / Public Reporting | D64: N/A — Incident (ShinyHunters vishing campaign) | E64: Vishing (voice phishing) campaign against Okta SSO/helpdesk accounts, attributed to ShinyHunters, used to pivot into downstream Salesforce and Snowflake environments; publicly reported to have compromised approximately 284 million patient records at McKesson | F64: IT — Identity & Access (Social Engineering) | G64: SSO / Identity Provider (Okta) and Downstream SaaS (Salesforce, Snowflake) | H64: Okta SSO; connected Salesforce and Snowflake tenants | I64: NIST CSF 2.0: PR.AA-01, PR.AT-01 | NIST 800-53: IA-2, AT-2 | ISO 27001: A.6.3, A.8.5 | HIPAA: 164.312(a)(1) | J64: IA — Identification & Authentication (Social Engineering Resistance) | K64: 5 | L64: 5 | M64: =K64*L64 | N64: Critical | O64: Critical | P64: Varies by organization; most orgs still rely on phone-verifiable helpdesk resets and non-phishing-resistant MFA | Q64: Medium (post-hardening; vishing resistance is a people+process control, not a single patch) | R64: Implement phishing-resistant MFA (FIDO2/WebAuthn) for SSO and helpdesk-privileged accounts; require out-of-band identity verification for any helpdesk-initiated credential reset; review Okta/downstream SaaS conditional-access policies for anomalous session or admin-console activity | S64: N/A — governance/awareness control, not CIS-mapped | T64: Blaise Kingko | U64: Open — Governance/Awareness | V64: 2026-10-05 | W64: 2026-09-07 | X64: Register-only governance/incident entry (no patchable CVE) — logged given scale (284M records reported) and direct relevance to identity-provider hardening posture. Healthcare-sector victim (McKesson) brings HIPAA Security Rule into framework scope alongside standard NIST/ISO stack.
A65: RR-061 | B65: 2026-09-21 | C65: CISA KEV | D65: CVE-2026-76460; CVE-2026-20130; CVE-2026-20192; CVE-2026-20234; CVE-2026-20194; CVE-2026-20237; CVE-2026-20352 | E65: Cisco Identity Services Engine (ISE/ISE-PIC) — unauthenticated privileged-API auth bypass granting full admin access; six companion CVEs (injection, access control, credential protection, input validation, RADIUS DoS) | F65: IT-OT-Threats / Cloud-Security (IAM) | G65: Network Access Control / IAM | H65: Cisco ISE & ISE-PIC 3.1.0–3.5 Patch 3 | I65: NIST CSF 2.0: PR.AA-01, DE.CM-01 | NIST 800-53: IA-2, AC-3 | ISO 27001: A.8.9 | CIS Control 5 | J65: IA — Identification & Authentication | K65: 5 | L65: 5 | M65: =K65*L65 | N65: Critical | O65: Vendor patch available (3.1 P12/3.2 P11/3.3 P12/3.4 P7/3.5 P4) | P65: High | Q65: Apply emergency Cisco patch to all ISE/ISE-PIC nodes within CISA 3-day window; review admin/audit logs for unauthorized access predating patch | R65: CIS Control 5.4 — Restrict Administrator Privileges | S65: Blaise Kingko | T65: Open — Emergency | U65: 2026-09-24 | V65: 2026-09-21 | W65: Actively exploited per CISA KEV (added 2026-09-16/17). CVSS 10.0. Full 7-artifact bundle built (dual-category IT-OT-Threats/Cloud-Security). Highest-priority finding this run.
A66: RR-062 | B66: 2026-09-21 | C66: CISA KEV | D66: CVE-2026-76461 | E66: Cisco AsyncOS Secure Email Gateway — unauthenticated SQL injection escalating to root OS command execution | F66: IT-OT-Threats | G66: Email Security Gateway | H66: Cisco AsyncOS SEG 15.5 and earlier, 16.0, 16.5 (pre-fix) | I66: NIST CSF 2.0: PR.PS-04 | NIST 800-53: SI-10, SI-2 | ISO 27001: A.8.28 | CIS Control 7 | J66: SI — System Integrity | K66: 5 | L66: 5 | M66: =K66*L66 | N66: Critical | O66: Vendor patch available (15.5.5-0141/16.0.4-302/16.5.0-780) | P66: High | Q66: Apply fixed AsyncOS build immediately — CISA remediation deadline (2026-09-17) already passed; forensic log review for pre-patch compromise | R66: CIS Control 7.4 — Manage OS Vulnerabilities | S66: Blaise Kingko | T66: Open — Emergency / Overdue | U66: 2026-09-23 | V66: 2026-09-21 | W66: Actively exploited per CISA KEV (added 2026-09-14). CVSS 9.8. CISA deadline already elapsed as of this run. Full bundle built.
A67: RR-063 | B67: 2026-09-21 | C67: CISA KEV | D67: CVE-2025-39964; CVE-2026-53266; CVE-2025-39682 | E67: Linux Kernel — three actively-exploited flaws: AF_ALG crypto socket race condition, netfilter ebtables SNAT out-of-bounds write, kernel TLS receive-path condition-handling flaw | F67: IT-OT-Threats | G67: Server / Container Host OS | H67: Linux Kernel (multiple subsystems; specific version ranges not published by CISA) | I67: NIST CSF 2.0: PR.PS-02 | NIST 800-53: SI-2, CM-6 | ISO 27001: A.8.8 | CIS Control 7 | J67: SI — System Integrity | K67: 5 | L67: 4 | M67: =K67*L67 | N67: High | O67: Distribution kernel updates available; some affected products possibly EoL/EoS per CISA | P67: Medium | Q67: Deploy distribution kernel update containing all three fixes across server/container fleet; flag and scope upgrade for any EoL/EoS kernel versions found | R67: CIS Control 7.4 — Manage OS Vulnerabilities | S67: Blaise Kingko | T67: Open — Emergency | U67: 2026-10-05 | V67: 2026-09-21 | W67: All three actively exploited per Red Hat confirmation (2026-09-19), added to KEV 2026-09-18. Combined into one case per program convention for same-batch CVEs. Full bundle built.
A68: RR-064 | B68: 2026-09-21 | C68: MSRC | D68: CVE-2026-85889; CVE-2026-85885 | E68: Azure AI Foundry missing-authentication privilege escalation (CVSS 10.0) and Microsoft 365 Copilot command-injection privilege escalation (CVSS 9.9); both fixed server-side by Microsoft, no confirmed exploitation | F68: AI-Governance / Cloud-Security | G68: AI Development & Assistant Platform | H68: Azure AI Foundry (all versions); Microsoft 365 Copilot (all versions) | I68: NIST AI RMF: MAP 5.1 | ISO 42001: 8.4 | NIST CSF 2.0: PR.AA-05 | NIST 800-53: IA-2, SI-10 | J68: IA — Identification & Authentication | K68: 2 | L68: 5 | M68: =K68*L68 | N68: Critical | O68: Server-side Microsoft fix applied prior to disclosure; no customer patch required | P68: Low | Q68: Complete Azure AI Foundry log review for pre-fix (before 2026-09-17) privileged activity/service principal/role changes; obtain written Microsoft confirmation of Copilot remediation | R68: N/A — cloud-vendor-remediated | S68: Blaise Kingko | T68: Open — Verification | U68: 2026-09-26 | V68: 2026-09-21 | W68: No confirmed in-the-wild exploitation; vendor pre-disclosure fix. Second consecutive week of critical Azure AI-platform finding (see prior CosmosEscape case). Full bundle built, dual-category.
A69: RR-065 | B69: 2026-09-21 | C69: AWS Bulletin | D69: CVE-2026-86830; CVE-2026-86831 | E69: AWS TEAM (IAM Identity Center elevated access tool) incorrect privilege assignment; Amazon EKS Network Policy Agent pod-identifier collision bypassing cross-namespace NetworkPolicy enforcement | F69: Cloud-Security | G69: IAM Elevated-Access Tooling / EKS Network Isolation | H69: TEAM <1.5.1; Amazon VPC CNI Add-on 1.14.0–1.22.3 / Network Policy Agent <1.4.0 | I69: NIST CSF 2.0: PR.AA-05 | NIST 800-53: AC-6, SC-7 | ISO 27001: A.8.22 | CIS Control 6 | J69: AC — Access Control | K69: 3 | L69: 4 | M69: =K69*L69 | N69: High | O69: Vendor fixes available (TEAM v1.5.1+; VPC CNI Add-on v1.22.4+; Network Policy Agent v1.4.0+) | P69: Medium | Q69: Upgrade TEAM to v1.5.1+ and review recent elevated-access grants; upgrade EKS components and audit namespace names for hyphen-collision risk | R69: CIS Control 6.8 — Define and Maintain Role-Based Access Control | S69: Blaise Kingko | T69: Open | U69: 2026-09-26 | V69: 2026-09-21 | W69: No confirmed exploitation; both responsibly disclosed. Both findings defeat tooling specifically built to enforce least-privilege/isolation. Full bundle built.
A70: RR-066 | B70: 2026-09-21 | C70: NIST NVD | D70: CVE-2026-12944 | E70: IBM Langflow OSS — arbitrary Python code execution as root via unsandboxed socket/urllib imports in workflow components, enabling AWS credential theft via IMDSv1 SSRF | F70: AI-Governance / Cloud-Security | G70: AI Agent Workflow Platform | H70: IBM Langflow OSS 1.0.0–1.10.0 | I70: NIST AI RMF: MANAGE 4.1 | ISO 42001: 6.1.3 | NIST 800-53: SC-39, SC-7 | NIST CSF 2.0: PR.PS-01 | J70: SC — System & Communications Protection | K70: 4 | L70: 5 | M70: =K70*L70 | N70: Critical | O70: Vendor fix available beyond v1.10.0; no KEV listing as of this sweep | P70: Medium | Q70: Upgrade all Langflow instances beyond v1.10.0 immediately; enforce IMDSv2-only on all hosting instances; formal AI governance decision on production eligibility | R70: CIS Control 16 — Application Software Security | S70: Blaise Kingko | T70: Open — Emergency | U70: 2026-09-25 | V70: 2026-09-21 | W70: Fifth Langflow finding logged by this program since June 2026 (RR pattern). Elevated likelihood scoring reflects platform's established rapid-weaponization history. Full bundle built.
A71: RR-067 | B71: 2026-09-21 | C71: NIST NVD | D71: CVE-2026-93839; CVE-2026-61560; CVE-2026-58201; CVE-2026-55887; CVE-2026-58197; CVE-2026-91988 | E71: Six independent MCP-server/AI-agent-tooling CVEs: LightLLM unauthenticated node registration, GitLab MCP unauthenticated file exfiltration, Lokka Azure token theft via SSRF, docker/mcp-gateway YAML injection, ToolHive network-isolation gap, atomic-agents-stack cleartext-registry MITM RCE | F71: AI-Governance / Cloud-Security | G71: AI Agent Connector Tooling (MCP servers) | H71: LightLLM ≤1.2.0; mcp-gitlab <2.1.27; Lokka <2.1.2; docker/mcp-gateway 0.21.0–0.42.1; ToolHive CLI <0.30.1/Studio <0.38.0; atomic-agents-stack <1.1.0 | I71: NIST AI RMF: GOVERN 1.1 | ISO 42001: 6.1.2 | NIST 800-53: IA-2, SC-8 | NIST CSF 2.0: ID.SC-04 | J71: IA — Identification & Authentication | K71: 3 | L71: 5 | M71: =K71*L71 | N71: Critical | O71: Vendor fixes available for all six; no confirmed exploitation | P71: Medium | Q71: Inventory deployed MCP server products and patch all in-use affected instances; review Azure activity logs if Lokka in use; establish standing MCP-server vetting process | R71: CIS Control 16 — Application Software Security | S71: Blaise Kingko | T71: Open | U71: 2026-09-28 | V71: 2026-09-21 | W71: Third consecutive week of critical MCP/AI-agent-tooling findings (see RR-049 CoreBreak, RR-051/052 AWS Labs MCP). Program recommends standing MCP category going forward. Full bundle built.
A72: RR-068 | B72: 2026-09-21 | C72: CISA KEV | D72: CVE-2026-87886 | E72: Acronis Backup plugin for cPanel/WHM, Plesk, and DirectAdmin — incorrect default file permissions enabling local privilege escalation | F72: IT-OT-Threats | G72: Backup / Hosting Control Panel Plugin | H72: Acronis Backup plugin: cPanel/WHM <1.9.3.1021 (fixed 1.9.3 HF3); Plesk <1.8.11.638 (fixed 1.8.11); DirectAdmin <1.2.3.238 | I72: NIST CSF 2.0: PR.PS-01 | NIST 800-53: AC-6, CM-6 | CIS Control 5 | J72: AC — Access Control | K72: 5 | L72: 3 | M72: =K72*L72 | N72: High | O72: Vendor fix available; local-access precondition narrows realistic attacker population | P72: Low | Q72: Upgrade Acronis Backup plugin to fixed build for the applicable hosting panel | R72: CIS Control 5 — Account Management | S72: Blaise Kingko | T72: Open — Register-Only | U72: 2026-09-24 | V72: 2026-09-21 | W72: Actively exploited per CISA KEV (added 2026-09-16) but local-privilege-escalation with narrow precondition — register-only per RR-021/RR-034/RR-039 precedent (no full bundle for narrow-precondition findings).
A73: RR-069 | B73: 2026-09-21 | C73: CISA Advisory | D73: CVE-2026-62645; CVE-2026-62648; CVE-2026-62647; CVE-2026-62646; CVE-2026-62654; CVE-2026-62652 | E73: Siemens Reyrolle 7SR5 protection relay — missing-authentication vulnerability (CVSS 9.8) plus five companion findings (out-of-bounds write, debug info exposure) | F73: IT-OT-Threats | G73: OT — Protection Relay (grid/substation) | H73: Siemens Reyrolle 7SR5, versions pre-V2.70 | I73: NIST CSF 2.0: PR.AC-03 | NIST 800-53: IA-2 | IEC 62443 SL-2 | CIS Control 12 | J73: IA — Identification & Authentication | K73: 3 | L73: 5 | M73: =K73*L73 | N73: Critical | O73: Vendor firmware update to V2.70+ available; no confirmed exploitation as of this sweep | P73: Medium | Q73: Upgrade Reyrolle firmware to V2.70 or later; verify OT network segmentation isolates protection relays from general IT network | R73: CIS Control 12 — Network Infrastructure Management | S73: Blaise Kingko | T73: Open — Register-Only | U73: 2026-10-05 | V73: 2026-09-21 | W73: ICS advisory ICSA-26-258-05 (2026-09-15). Protection relay = grid/critical-infrastructure impact if exploited; register-only given no confirmed active exploitation, but flagged for OT-segment awareness.
...

Sheet 📊 Risk Dashboard
B1: GRC INTELLIGENCE DASHBOARD — BLAISE KINGKO
B3: RISK SUMMARY | E3: RISKS BY SOURCE
B4: Total Risks Identified | C4: =COUNTA('🛡️ Risk Register'!A5:A500) | E4: CISA KEV | F4: =COUNTIF('🛡️ Risk Register'!C5:C500,"CISA KEV")
B5: Critical Risks | C5: =COUNTIF('🛡️ Risk Register'!N5:N500,"Critical") | E5: NIST NVD | F5: =COUNTIF('🛡️ Risk Register'!C5:C500,"NIST NVD")
B6: High Risks | C6: =COUNTIF('🛡️ Risk Register'!N5:N500,"High") | E6: US-CERT | F6: =COUNTIF('🛡️ Risk Register'!C5:C500,"US-CERT")
B7: Medium Risks | C7: =COUNTIF('🛡️ Risk Register'!N5:N500,"Medium") | E7: AWS Security Bulletin | F7: =COUNTIF('🛡️ Risk Register'!C5:C500,"AWS Security Bulletin")
B8: Low Risks | C8: =COUNTIF('🛡️ Risk Register'!N5:N500,"Low") | E8: Azure Security Update | F8: =COUNTIF('🛡️ Risk Register'!C5:C500,"Azure Security Update")
B9: Open Risks | C9: =COUNTIF('🛡️ Risk Register'!U5:U500,"Open") | E9: AI Governance Update | F9: =COUNTIF('🛡️ Risk Register'!C5:C500,"AI Governance Update")
B10: Mitigating | C10: =COUNTIF('🛡️ Risk Register'!U5:U500,"Mitigating") | E10: NIST Framework Update | F10: =COUNTIF('🛡️ Risk Register'!C5:C500,"NIST Framework Update")
B11: Closed This Period | C11: =COUNTIF('🛡️ Risk Register'!U5:U500,"Closed") | E11: ISO Update | F11: =COUNTIF('🛡️ Risk Register'!C5:C500,"ISO Update")
B12: AI/ML Risks | C12: =COUNTIFS('🛡️ Risk Register'!F5:F500,"AI/ML*") | E12: Internal Assessment | F12: =COUNTIF('🛡️ Risk Register'!C5:C500,"Internal Assessment")
B13: Cloud Risks | C13: =COUNTIFS('🛡️ Risk Register'!F5:F500,"Cloud*")
B14: OT/ICS Risks | C14: =COUNTIFS('🛡️ Risk Register'!F5:F500,"OT*")
B15: Past Due (Overdue) | C15: =COUNTIFS('🛡️ Risk Register'!V5:V500,"<"&TODAY(),'🛡️ Risk Register'!U5:U500,"Open")
B17: FRAMEWORK COVERAGE
B18: NIST CSF 2.0 | C18: =COUNTIF('🛡️ Risk Register'!I5:I500,"*NIST CSF*")
B19: NIST 800-53 | C19: =COUNTIF('🛡️ Risk Register'!I5:I500,"*800-53*")
B20: ISO 27001 | C20: =COUNTIF('🛡️ Risk Register'!I5:I500,"*ISO 27001*")
B21: CIS Controls | C21: =COUNTIF('🛡️ Risk Register'!I5:I500,"*CIS Control*")
B22: NIST AI RMF | C22: =COUNTIF('🛡️ Risk Register'!I5:I500,"*NIST AI RMF*")
B23: ISO 42001 | C23: =COUNTIF('🛡️ Risk Register'!I5:I500,"*ISO 42001*")
B24: EU AI Act | C24: =COUNTIF('🛡️ Risk Register'!I5:I500,"*EU AI Act*")

Sheet 🔥 Risk Heat Map
B1: RISK HEAT MAP — LIKELIHOOD vs IMPACT
A3: LIKELIHOOD ↓ | B3: IMPACT →
B4: 1 — Minimal | C4: 2 — Minor | D4: 3 — Moderate | E4: 4 — Major | F4: 5 — Catastrophic | H4: LEGEND
A5: 5 — Almost Certain | B5: 5 Medium | C5: 10 High | D5: 15 Critical | E5: 20 Critical | F5: 25 Critical | H5: Critical (Score 20-25)
A6: 4 — Likely | B6: 4 Low | C6: 8 Medium | D6: 12 High | E6: 16 Critical | F6: 20 Critical | H6: High (Score 10-19)
A7: 3 — Possible | B7: 3 Low | C7: 6 Medium | D7: 9 Medium | E7: 12 High | F7: 15 Critical | H7: Medium (Score 5-9)
A8: 2 — Unlikely | B8: 2 Low | C8: 4 Low | D8: 6 Medium | E8: 8 Medium | F8: 10 High | H8: Low (Score 1-4)
A9: 1 — Rare | B9: 1 Low | C9: 2 Low | D9: 3 Low | E9: 4 Low | F9: 5 Medium

Sheet 📡 Intel Sources
B1: INTELLIGENCE MONITORING SOURCES — BLAISE KINGKO GRC PROGRAM
B2: SOURCE | C2: URL / FEED | D2: CATEGORY | E2: FREQUENCY | F2: FRAMEWORK RELEVANCE
B3: CISA KEV | C3: https://www.cisa.gov/known-exploited-vulnerabilities-catalog | D3: Threat Intel | E3: Daily | F3: NIST CSF: DE.CM | NIST 800-53: RA-5, SI-2
B4: CISA Advisories | C4: https://www.cisa.gov/news-events/cybersecurity-advisories | D4: Threat Intel | E4: Weekly | F4: NIST CSF: DE.AE | NIST 800-53: IR-4, SI-5
B5: US-CERT Alerts | C5: https://www.cisa.gov/uscert/ncas/alerts | D5: Threat Intel | E5: Weekly | F5: NIST CSF: RS.CO | NIST 800-53: IR-6
B6: NIST NVD | C6: https://nvd.nist.gov/vuln/search | D6: Vulnerability | E6: Weekly | F6: NIST 800-53: RA-5 | CIS Control 7
B7: NIST 800-53 Updates | C7: https://csrc.nist.gov/publications/detail/sp/800-53/rev-5/final | D7: Framework | E7: Quarterly | F7: NIST 800-53 all control families
B8: NIST CSF 2.0 Updates | C8: https://www.nist.gov/cyberframework | D8: Framework | E8: Quarterly | F8: NIST CSF 2.0 all functions
B9: NIST AI RMF Updates | C9: https://www.nist.gov/artificial-intelligence | D9: AI Governance | E9: Monthly | F9: NIST AI RMF: GOVERN, MAP, MEASURE, MANAGE
B10: ISO 27001 Updates | C10: https://www.iso.org/standard/27001 | D10: Framework | E10: Annual | F10: ISO 27001 all clauses and Annex A
B11: ISO 42001 Updates | C11: https://www.iso.org/standard/81230.html | D11: AI Governance | E11: Annual | F11: ISO 42001 all clauses
B12: EU AI Act | C12: https://artificialintelligenceact.eu | D12: AI Governance / Regulatory | E12: Monthly | F12: EU AI Act Articles 9, 10, 11, 13, 17
B13: AWS Security Bulletins | C13: https://aws.amazon.com/security/security-bulletins/ | D13: Cloud Security | E13: Weekly | F13: NIST 800-53: SI-2 | CIS Control 7 | CSF: PR.PS
... B17: MITRE ATLAS (AI) | C17: https://atlas.mitre.org | D17: AI Threat Intel | E17: Monthly | F17: NIST AI RMF: MAP 5 | ISO 42001: 6.1.2

Sheet 📋 Version Log
A1: VERSION LOG — GRC Intelligence Risk Register
A2: Authoritative history of register versions. The LIVE file (GRC_Intelligence_Risk_Register.xlsx) always reflects the version marked LIVE below. Dated snapshot files in this folder are frozen, read-only archives of past versions — do not edit them.
A4: Version | B4: Date | C4: Status | D4: Snapshot Filename | E4: Risk IDs Added/Changed This Version | F4: Total Open Risks | G4: Summary of Changes
A5: v1 | B5: 2026-06-01 | C5: ARCHIVED | D5: GRC_Intelligence_Risk_Register_2026-06-01.xlsx | E5: RR-001 – RR-005 | F5: 5 | G5: Initial register established. Baseline cloud security and AI governance risks logged.
A6: v2 | B6: 2026-06-08 | C6: ARCHIVED | D6: GRC_Intelligence_Risk_Register_2026-06-08.xlsx | E6: RR-006 – RR-010 | F6: 10 | G6: Added 5 new risks (AWS/Azure cloud platform CVEs, Magento KEV, EU AI Act draft guidance, Android KEV). NOTE: these 5 rows were entered with a 2-column data shift (Affected Asset/Affected System fields omitted), corrupting Likelihood/Impact/Risk Score/Risk Rating placement for RR-006–RR-010. Not caught at the time — corrected retroactively in v4 (see below).
A7: v3 | B7: 2026-06-15 | C7: ARCHIVED | D7: GRC_Intelligence_Risk_Register_2026-06-15.xlsx | E7: RR-011 – RR-016 | F7: 16 | G7: Added 6 new risks. No structural issues introduced this version.
A8: v4 | B8: 2026-06-22 | C8: ARCHIVED | D8: GRC_Intelligence_Risk_Register_2026-06-22.xlsx (archived copy of this version) | E8: RR-017 – RR-022 (new); RR-017 escalated (-UPDATE) over prior Cisco SD-WAN entry; RR-006–RR-010 DATA QUALITY FIX (column alignment corrected, Affected Asset/Affected System reconstructed and backfilled) | F8: 22 | G8: Added 6 new risks. Fixed the v2 column-misalignment defect in RR-006–RR-010: shifted FRAMEWORK MAPPING through NOTES back into their correct columns and reconstructed the missing Affected Asset/Affected System values from each row's threat description. Verified Likelihood × Impact = Risk Score and Risk Score → Risk Rating banding for all 5 corrected rows. Introduced this version-labeling convention (LIVE vs. ARCHIVED banners + this log) so the canonical file is always unambiguous.
A9: v5 | B9: 2026-06-29 | C9: ARCHIVED | D9: GRC_Intelligence_Risk_Register_2026-06-29.xlsx (archived copy of this version) | E9: RR-023 – RR-027 (new); RR-004 and RR-009 REVISED in place (EU AI Act deadline-delay amendments) | F9: 27 | G9: Added 5 new risks (Lantronix EDS5000 KEV, Ubiquiti UniFi OS KEV triple-CVE chain, PTC Windchill/FlexPLM KEV, Cisco Unified CM KEV, Daktronics ICS Advisory). Revised RR-004 and RR-009 in place to reflect European Parliament's finalized EU AI Act deadline-delay amendments (approved 2026-06-16) and consultation closure (2026-06-23) — no new rows created for this regulatory update per dedup/escalation rules. Dedup check performed against all CVE/Advisory IDs on file; no duplicate rows found.
A10: v6 | B10: 2026-07-13 | C10: ARCHIVED | D10: GRC_Intelligence_Risk_Register_2026-07-13.xlsx (archived copy of this version) | E10: RR-028 – RR-034 (new) | F10: 34 | G10: Added 7 new risks: Langflow AI agent platform auth bypass (CVE-2026-55255, dual-category AI-Governance/Cloud-Security, first AI agent platform in CISA KEV), Adobe ColdFusion RDS path traversal RCE (CVE-2026-48282), and a 4-CVE combined Joomla extension ecosystem file-upload RCE finding (SP Page Builder, Joomlack Page Builder, iCagenda, Balbooa Forms — CVE-2026-48908/56290/48939/56291), plus a register-only entry for the joint NSA/CISA/FBI router-hygiene advisory (Russian FSB Center 16 targeting). Dedup check performed against all CVE/Advisory IDs on file; no duplicate rows found. Column-alignment spot check run and passed programmatically for all 7 new rows before save.
